<?xml version='1.0'?>
<robot name="my_robot" xmlns:xacro="http://www.ros.org/wiki/xacro">

  <link name="robot_footprint"></link>

  <xacro:include filename="$(find my_robot)/urdf/my_robot.gazebo" />

	<xacro:macro name="wheel" params="name">  
	    
	    <link name="${name}">
				<pose>0 0 0 0 0 0</pose>
			
				<inertial>
				  <mass value="1.0"/>
				  <origin xyz="0.0 0 0" rpy=" 0 1.5707 1.5707"/>
				  <inertia
				      ixx="0.1" ixy="0" ixz="0"
				      iyy="0.1" iyz="0"
				      izz="0.1"
				  />
				</inertial>

				<collision name='collision'>
				  <origin xyz="0 0 0" rpy=" 0 1.5707 1.5707"/> 
				  <geometry>
				    <cylinder radius="0.1" length="0.05"/>
				  </geometry>
				</collision>

				<visual name='visual'>
				  <origin xyz="0 0 0" rpy=" 0 1.5707 1.5707"/> 
				  <geometry>
				    <cylinder radius="0.1" length="0.05"/>
				  </geometry>
				</visual>
				
	    </link>

	</xacro:macro>

  <joint name="robot_footprint_joint" type="fixed">
    <origin xyz="0 0 0" rpy="0 0 0" />
    <parent link="robot_footprint"/>
    <child link="chassis" />
  </joint>

  <link name='chassis'>
    <pose>0 0 0.1 0 0 0</pose>

    <inertial>
      <mass value="10.0"/>
      <origin xyz="0.0 0 0" rpy="0 0 0"/>
      <inertia
          ixx="0.1" ixy="0" ixz="0"
          iyy="0.1" iyz="0"
          izz="0.1"
      />
    </inertial>

    <collision name='collision'>
      <origin xyz="0 0 0" rpy="0 0 0"/> 
      <geometry>
        <box size=".4 .2 .05"/>
      </geometry>
    </collision>

    <visual name='chassis_visual'>
      <origin xyz="0 0 0" rpy="0 0 0"/>
      <geometry>
        <box size=".4 .2 .05"/>
      </geometry>
    </visual>

  </link>
  
  <gazebo reference="chassis">
    <material>Gazebo/Yellow</material>
  </gazebo>

	<xacro:wheel name="left_wheel_upper"/>
	<xacro:wheel name="right_wheel_upper"/>
	<xacro:wheel name="left_wheel_bottom"/>
	<xacro:wheel name="right_wheel_bottom"/>
	
  <joint type="continuous" name="front_left_wheel_joint">
    <origin xyz="0.2 0.15 0" rpy="0 0 0"/>
    <child link="left_wheel_upper"/>
    <parent link="chassis"/>
    <axis xyz="0 1 0" rpy="0 0 0"/>
    <limit effort="10000" velocity="1000"/>
    <dynamics damping="1.0" friction="0.5"/>
  </joint>

  <joint type="continuous" name="front_right_wheel_joint">
    <origin xyz="0.2 -0.15 0" rpy="0 0 0"/>
    <child link="right_wheel_upper"/>
    <parent link="chassis"/>
    <axis xyz="0 1 0" rpy="0 0 0"/>
    <limit effort="10000" velocity="1000"/>
    <dynamics damping="1.0" friction="0.5"/>
  </joint>
  
  <joint type="continuous" name="back_left_wheel_joint">
    <origin xyz="-0.2 0.15 0" rpy="0 0 0"/>
    <child link="left_wheel_bottom"/>
    <parent link="chassis"/>
    <axis xyz="0 1 0" rpy="0 0 0"/>
    <limit effort="10000" velocity="1000"/>
    <dynamics damping="1.0" friction="0.5"/>
  </joint>

  <joint type="continuous" name="back_right_wheel_joint">
    <origin xyz="-0.2 -0.15 0" rpy="0 0 0"/>
    <child link="right_wheel_bottom"/>
    <parent link="chassis"/>
    <axis xyz="0 1 0" rpy="0 0 0"/>
    <limit effort="10000" velocity="1000"/>
    <dynamics damping="1.0" friction="0.5"/>
  </joint>

  <link name='camera'>
    <pose>0 0 0 0 0 0</pose>

    <inertial>
      <mass value="0.1"/>
      <origin xyz="0.0 0 0" rpy="0.0 0 0"/>
      <inertia
          ixx="1e-6" ixy="0" ixz="0"
          iyy="1e-6" iyz="0"
          izz="1e-6"
      />
    </inertial>

    <collision name='collision'>
      <origin xyz="0 0 0" rpy=" 0 0 0"/> 
      <geometry>
        <box size="0.05 0.05 0.05"/>
      </geometry>
    </collision>

    <visual name='visual'>
      <origin xyz="0 0 0" rpy="0 0 0"/> 
      <geometry>
        <box size="0.05 0.05 0.05"/>
      </geometry>
    </visual>

  </link>

  <link name="camera_link_optical"></link>

  <joint name="camera_optical_joint" type="fixed">
    <origin xyz="0 0 0" rpy="-1.5707 0 -1.5707"/>
    <parent link="camera"/>
    <child link="camera_link_optical"/>
  </joint>

  <joint type="fixed" name="camera_joint">
    <origin xyz=".2 0 0" rpy="0 0 0"/>
    <child link="camera"/>
    <parent link="chassis"/>
    <axis xyz="0 1 0" rpy="0 0 0"/>
  </joint>

  <link name='hokuyo'>
    <pose>0 0 0 0 0 0</pose>

    <inertial>
      <mass value="1e-5"/>
      <origin xyz="0.0 0 0" rpy="0.0 0 0"/>
      <inertia
          ixx="1e-6" ixy="0" ixz="0"
          iyy="1e-6" iyz="0"
          izz="1e-6"
      />
    </inertial>

    <collision name='collision'>
      <origin xyz="0 0 0" rpy=" 0 0 0"/> 
      <geometry>
        <box size="0.1 0.1 0.1"/>
      </geometry>
    </collision>

    <visual name='hokuyo_visual'>
      <origin xyz="0 0 0" rpy="0 0 0"/> 
      <geometry>
        <mesh filename="package://my_robot/meshes/hokuyo.dae"/>
      </geometry>
    </visual>
  </link>

  <joint type="fixed" name="hokuyo_joint">
    <origin xyz="0.1 0 0.1" rpy="0 0 0"/>
    <child link="hokuyo"/>
    <parent link="chassis"/>
    <axis xyz="0 1 0" rpy="0 0 0"/>
  </joint>
  
</robot>
